Workbook

Sheet README
A1: Nike (NKE) 5-year DCF model
A2: Built 2026-10-04 by scripts/05_excel_dcf_model.py. Valuation date 2026-10-02. All money in USD millions unless labelled. Fiscal year ends May 31.
A4: How the tabs connect (money flows left to right)
A5: 1. Assumptions: every input. Change a yellow cell and everything else updates.
A6: 2. Historicals: Nike's FY2017-FY2026 10-K figures and ratios. Use its averages to judge the assumptions.
A7: 3. Sources: the SEC filing (accession number) behind each historical figure.
A8: 4. WACC: builds the discount rate from the market inputs on Assumptions.
A9: 5. Forecast: starts from FY2026 actual revenue (Historicals), sets FY2027 from Nike's guidance (revenue -8%, margin 5.55%), and applies the Assumptions to get FY2027-FY2031 free cash flow (FCFF).
A10: 6. Valuation: discounts the Forecast's FCFF at the WACC, adds a terminal value for the years after FY2031, adds cash, subtracts debt, divides by shares, and compares with the share price.
A12: Colour code
A13: Blue on yellow = an input you can change (Assumptions tab).
A14: Blue = a historical number typed in from SEC filings.
... A24: The terminal value builds FY2032 as a normal year growing 2.5% (working capital grows with that 2.5%), so FY2031's own growth-driven working-capital spending is not repeated forever.

Sheet Assumptions
A1: Assumptions: every input to the model lives on this tab
A2: Blue numbers on a yellow background are inputs: change them here and the whole model updates. Official copy: scripts/assumptions.py (re-run scripts/05_excel_dcf_model.py to rebuild).
A4: Input | B4: Value | C4: Unit | D4: Source | E4: Date set | F4: Name used in formulas
A5: 1. Valuation setup
A6: Valuation date (share price date) | B6: 46297 | C6: date | D6: judgment: last trading day before this model was built (2026-10-04 was a Sunday) | E6: 2026-10-04 | F6: Valuation_Date
A7: Base year (last actual fiscal year) | B7: 2026 | C7: fiscal year | D7: latest full fiscal year in the 10-K (FY2026 ended 2026-05-31) | E7: 2026-10-04 | F7: Base_FY
A8: Share of FY2027 cash flow still to come | B8: 0.75 | C8: fraction of FY2027 cash flow still to come | D8: Q1 FY2027 (Jun-Aug 2026) is already over and its cash is in the 2026-08-31 balance sheet, so only 9 of 12 months count | E8: 2026-10-04 | F8: Share_Of_FY2027_Remaining
A9: 2. Revenue growth by year (forecast)
A10: Revenue growth FY2027 | B10: -0.08 | C10: fraction per year, by fiscal year | D10: FY2027 = midpoint of Nike's guidance, revenue to 'decline high-single digits' (read as -7% to -9%; Q1 FY2027 earnings release, 8-K 0000320187-26-000184, Ex. 99.1, 2026-10-01; see GUIDANCE_FY2027). History: +1% until 2026-10-04 22:35, then -1.09% (Q1 actual + Q2-Q4 flat) until 2026-10-04 23:00. FY2028-31: judgment, a gradual return toward, but below, Nike's FY2016-FY2024 compound annual growth of 5.9% (output/06a_nike_history_fy1993_fy2026.csv) | E10: 2026-10-04 | F10: Growth_FY2027
A11: Revenue growth FY2028 | B11: 0.03 | C11: fraction per year, by fiscal year | D11: FY2027 = midpoint of Nike's guidance, revenue to 'decline high-single digits' (read as -7% to -9%; Q1 FY2027 earnings release, 8-K 0000320187-26-000184, Ex. 99.1, 2026-10-01; see GUIDANCE_FY2027). History: +1% until 2026-10-04 22:35, then -1.09% (Q1 actual + Q2-Q4 flat) until 2026-10-04 23:00. FY2028-31: judgment, a gradual return toward, but below, Nike's FY2016-FY2024 compound annual growth of 5.9% (output/06a_nike_history_fy1993_fy2026.csv) | E11: 2026-10-04 | F11: Growth_FY2028
A12: Revenue growth FY2029 | B12: 0.04 | C12: fraction per year, by fiscal year | D12: FY2027 = midpoint of Nike's guidance, revenue to 'decline high-single digits' (read as -7% to -9%; Q1 FY2027 earnings release, 8-K 0000320187-26-000184, Ex. 99.1, 2026-10-01; see GUIDANCE_FY2027). History: +1% until 2026-10-04 22:35, then -1.09% (Q1 actual + Q2-Q4 flat) until 2026-10-04 23:00. FY2028-31: judgment, a gradual return toward, but below, Nike's FY2016-FY2024 compound annual growth of 5.9% (output/06a_nike_history_fy1993_fy2026.csv) | E12: 2026-10-04 | F12: Growth_FY2029
A13: Revenue growth FY2030 | B13: 0.04 | C13: fraction per year, by fiscal year | D13: FY2027 = midpoint of Nike's guidance, revenue to 'decline high-single digits' (read as -7% to -9%; Q1 FY2027 earnings release, 8-K 0000320187-26-000184, Ex. 99.1, 2026-10-01; see GUIDANCE_FY2027). History: +1% until 2026-10-04 22:35, then -1.09% (Q1 actual + Q2-Q4 flat) until 2026-10-04 23:00. FY2028-31: judgment, a gradual return toward, but below, Nike's FY2016-FY2024 compound annual growth of 5.9% (output/06a_nike_history_fy1993_fy2026.csv) | E13: 2026-10-04 | F13: Growth_FY2030
A14: Revenue growth FY2031 | B14: 0.04 | C14: fraction per year, by fiscal year | D14: FY2027 = midpoint of Nike's guidance, revenue to 'decline high-single digits' (read as -7% to -9%; Q1 FY2027 earnings release, 8-K 0000320187-26-000184, Ex. 99.1, 2026-10-01; see GUIDANCE_FY2027). History: +1% until 2026-10-04 22:35, then -1.09% (Q1 actual + Q2-Q4 flat) until 2026-10-04 23:00. FY2028-31: judgment, a gradual return toward, but below, Nike's FY2016-FY2024 compound annual growth of 5.9% (output/06a_nike_history_fy1993_fy2026.csv) | E14: 2026-10-04 | F14: Growth_FY2031
A15: Growth adjustment added to FY2028-31 (scenario testing, 0 = base case; FY2027 stays at guidance) | B15: 0 | C15: fraction per year, added to every forecast year's growth | D15: setting for scenario testing (e.g. Excel Goal Seek to find the growth that matches the share price); 0 = base case | E15: 2026-10-04 | F15: Growth_Adjustment
A16: 3. Margins, tax and reinvestment (forecast)
A17: FY2027 operating margin (from Nike's guidance) | B17: 0.0555 | C17: fraction of revenue (adjusted: before Pace restructuring charges) | D17: derived from Nike's FY2027 guidance (GUIDANCE_FY2027, midpoints): adjusted EPS 1.25 x 1,484.2m diluted shares / (1 - 25% tax) - 103m non-operating income = USD 2,371m operating income, / (46,398m x (1 - 8%)) revenue = 5.55%. Script 10 repeats the steps and checks this value (output/10_guidance_margin.csv). Set 2026-10-04 at Eric's request to build the guidance into the base case; before that FY2027 sat on the straight line from FY2026's 8.2% (9.1%) | E17: 2026-10-04 | F17: FY2027_Margin
A18: Target operating margin | B18: 0.125 | C18: fraction of revenue (12.5%) | D18: judgment: Nike's FY2017-FY2024 operating margin, simple average of the 8 years = 12.5% (output/02_historical_metrics.csv), i.e. a full recovery to pre-FY2025 levels | E18: 2026-10-04 | F18: Target_Margin
A19: Years after FY2026 to reach the target margin (straight line from FY2027's guidance margin) | B19: 5 | C19: years after FY2026 (FY2027 is the guidance margin; from there a straight line to target by FY2031) | D19: judgment | E19: 2026-10-04 | F19: Years_To_Target
A20: Tax rate on operating income | B20: 0.18 | C20: fraction of operating income | D20: judgment: about Nike's FY2023-FY2026 average effective rate (17.6%, output/02_historical_metrics.csv) | E20: 2026-10-04 | F20: Tax_Rate
A21: Depreciation & amortization, % of revenue | B21: 0.017 | C21: fraction of revenue | D21: Nike FY2017-FY2026 average depreciation & amortization / revenue = 1.72% (10-K cash flow statements) | E21: 2026-10-04 | F21: DA_Pct
A22: Capital expenditures, % of revenue | B22: 0.02 | C22: fraction of revenue | D22: judgment: Nike FY2017-FY2026 average capex / revenue = 2.09%; FY2025-26 (0.9%, 1.5%) look cut back during the downturn, so we assume a return toward the average, a bit above D&A so the asset base grows | E22: 2026-10-04 | F22: Capex_Pct
A23: Operating working capital, % of revenue | B23: 0.115 | C23: fraction of revenue | D23: Nike FY2017-FY2026 average operating working capital / revenue = 11.4% (10-K balance sheets). Operating working capital = receivables + inventories + prepaid & other current assets - accounts payable - accrued liabilities. FY2026 was 12.7%, so FY2027 releases some cash | E23: 2026-10-04 | F23: NWC_Pct
A24: 4. Terminal value
A25: Cash flow growth forever after FY2031 | B25: 0.025 | C25: fraction per year, forever after FY2031 | D25: judgment: roughly long-run inflation plus a little real growth; kept below the risk-free rate | E25: 2026-10-04 | F25: Terminal_Growth
A26: 5. Market inputs for the discount rate (NOT from the SEC)
A27: Share price (USD) | B27: 33.87 | C27: USD per share | D27: Yahoo Finance NKE close on 2026-10-02 (03_market_inputs.py); NON-SEC | E27: 2026-10-04 | F27: Share_Price
A28: Risk-free rate (10-year US Treasury yield) | B28: 0.05277 | C28: fraction per year (5.277%) | D28: 10-year US Treasury yield, Yahoo ^TNX close on 2026-10-02 (03_market_inputs.py); NON-SEC | E28: 2026-10-04 | F28: Risk_Free
A29: Beta (how much Nike's stock moves with the market) | B29: 1.092 | C29: multiple of market moves | D29: regression of 60 monthly Nike returns on S&P 500 returns, Oct-2021 to Sep-2026 (03_market_inputs.py, output/03_beta_summary.csv) | E29: 2026-10-04 | F29: Nike_Beta
A30: Equity risk premium | B30: 0.0409 | C30: fraction per year (4.09%) | D30: Damodaran implied US equity risk premium on 2026-09-01, 'ERP (T12m)' series, his latest monthly figure before the 2026-10-02 valuation date. Verified in his ERPbymonth.xlsx, saved in data/raw/damodaran/ (downloaded 2026-10-04). Changed from 4.23% (his 2026-01-01 figure) on 2026-10-04 so the premium is as current as the share price and risk-free rate. NON-SEC | E30: 2026-10-04 | F30: ERP
A31: Nike's borrowing spread over the risk-free rate | B31: 0.008 | C31: fraction per year over the risk-free rate (0.8%) | D31: judgment: typical spread for a high-grade (A/AA) US corporate borrower like Nike | E31: 2026-10-04 | F31: Debt_Spread
A32: Tax rate saved on interest | B32: 0.21 | C32: fraction | D32: US federal statutory corporate tax rate (interest is deducted mostly in the US) | E32: 2026-10-04 | F32: Tax_On_Interest
A33: 6. Latest balance sheet and shares (SEC Q1 FY2027 10-Q, 2026-08-31)
A34: Cash and equivalents (USD m) | B34: 6903 | C34: USD millions | D34: SEC 10-Q for the quarter ended 2026-08-31, accession 0000320187-26-000193, filed 2026-10-02, XBRL tag CashAndCashEquivalentsAtCarryingValue | E34: 2026-10-04 | F34: Cash
A35: Short-term investments (USD m) | B35: 1465 | C35: USD millions | D35: SEC 10-Q for the quarter ended 2026-08-31, accession 0000320187-26-000193, filed 2026-10-02, XBRL tag DebtSecuritiesAvailableForSaleExcludingAccruedInterestCurrent | E35: 2026-10-04 | F35: ST_Investments
A36: Long-term debt, non-current (USD m) | B36: 5893 | C36: USD millions | D36: SEC 10-Q for the quarter ended 2026-08-31, accession 0000320187-26-000193, filed 2026-10-02, XBRL tag LongTermDebtNoncurrent | E36: 2026-10-04 | F36: Debt_LT_Noncurrent
A37: Current portion of long-term debt (USD m) | B37: 2000 | C37: USD millions | D37: SEC 10-Q for the quarter ended 2026-08-31, accession 0000320187-26-000193, filed 2026-10-02, XBRL tag LongTermDebtCurrent | E37: 2026-10-04 | F37: Debt_LT_Current
A38: Notes payable / short-term borrowings (USD m) | B38: 0 | C38: USD millions | D38: no value at 2026-08-31; treated as 0 (XBRL tag ShortTermBorrowings) | E38: 2026-10-04 | F38: Debt_Short_Term
A39: Diluted shares (weighted average for the quarter) | B39: 1484.2 | C39: millions | D39: SEC 10-Q for the quarter ended 2026-08-31, accession 0000320187-26-000193, filed 2026-10-02, XBRL tag WeightedAverageNumberOfDilutedSharesOutstanding. Weighted average, not the exact 2026-08-31 count, which the SEC data file lacks | E39: 2026-10-04 | F39: Shares
A40: 7. Presentation only
A41: Sensitivity table: WACC step | B41: 0.005 | C41: fraction (0.5 percentage points between columns of the sensitivity table) | D41: judgment (presentation only) | E41: 2026-10-04 | F41: Sens_WACC_Step
...

Sheet Historicals
A1: Historicals: Nike FY2017-FY2026 (USD millions; fiscal year ends May 31)
A2: Blue = number from Nike's 10-K (filing details on the Sources tab). Black = formula. Columns L and M average the ratios so you can compare them with the Assumptions tab.
A4: Line item | B4: FY2017 | C4: FY2018 | D4: FY2019 | E4: FY2020 | F4: FY2021 | G4: FY2022 | H4: FY2023 | I4: FY2024 | J4: FY2025 | K4: FY2026 | L4: Avg FY2017-26 | M4: Avg FY2022-26 | N4: How it is calculated
A5: Income statement
A6: Revenue | B6: 34350 | C6: 36397 | D6: 39117 | E6: 37403 | F6: 44538 | G6: 46710 | H6: 51217 | I6: 51362 | J6: 46309 | K6: 46398 | N6: SEC 10-K
A7: Gross profit | B7: 15312 | C7: 15956 | D7: 17474 | E7: 16241 | F7: 19962 | G7: 21479 | H7: 22292 | I7: 22887 | J7: 19790 | K7: 19911 | N7: SEC 10-K
A8: Selling & administrative expense | B8: 10563 | C8: 11511 | D8: 12702 | E8: 13126 | F8: 13025 | G8: 14804 | H8: 16377 | I8: 16576 | J8: 16088 | K8: 16114 | N8: SEC 10-K
A9: Operating income | B9: =B7-B8 -> 4749 | C9: =C7-C8 -> 4445 | D9: =D7-D8 -> 4772 | E9: =E7-E8 -> 3115 | F9: =F7-F8 -> 6937 | G9: =G7-G8 -> 6675 | H9: =H7-H8 -> 5915 | I9: =I7-I8 -> 6311 | ... K9: =K7-K8 -> 3797 | N9: Gross profit - S&A (Nike reports no operating income line)
A10: Income before income taxes | B10: 4886 | C10: 4325 | D10: 4801 | E10: 2887 | F10: 6661 | G10: 6651 | H10: 6201 | I10: 6700 | J10: 3885 | K10: 3900 | N10: SEC 10-K
A11: Income tax expense | B11: 646 | C11: 2392 | D11: 772 | E11: 348 | F11: 934 | G11: 605 | H11: 1131 | I11: 1000 | J11: 666 | K11: 792 | N11: SEC 10-K
A12: Net income | B12: 4240 | C12: 1933 | D12: 4029 | E12: 2539 | F12: 5727 | G12: 6046 | H12: 5070 | I12: 5700 | J12: 3219 | K12: 3108 | N12: SEC 10-K
A13: Cash flow statement
A14: Operating cash flow | B14: 3846 | C14: 4955 | D14: 5903 | E14: 2485 | F14: 6657 | G14: 5188 | H14: 5841 | I14: 7429 | J14: 3698 | K14: 2868 | N14: SEC 10-K
A15: Depreciation & amortization | B15: 706 | C15: 747 | D15: 705 | E15: 721 | F15: 744 | G15: 717 | H15: 703 | I15: 796 | J15: 775 | K15: 747 | N15: SEC 10-K
A16: Capital expenditures | B16: 1105 | C16: 1028 | D16: 1119 | E16: 1086 | F16: 695 | G16: 758 | H16: 969 | I16: 812 | J16: 430 | K16: 684 | N16: SEC 10-K
A17: Free cash flow (simple) | B17: =B14-B16 -> 2741 | C17: =C14-C16 -> 3927 | D17: =D14-D16 -> 4784 | E17: =E14-E16 -> 1399 | F17: =F14-F16 -> 5962 | G17: =G14-G16 -> 4430 | H17: =H14-H16 -> 4872 | I17: =I14-I16 -> 6617 | ... K17: =K14-K16 -> 2184 | N17: Operating cash flow - capex (project definition)
A18: Balance sheet (at May 31)
A19: Cash and equivalents | B19: 3808 | C19: 4249 | D19: 4466 | E19: 8348 | F19: 9889 | G19: 8574 | H19: 7441 | I19: 9860 | J19: 7464 | K19: 7563 | N19: SEC 10-K
A20: Short-term investments | B20: 2371 | C20: 996 | D20: 197 | E20: 439 | F20: 3587 | G20: 4423 | H20: 3234 | I20: 1722 | J20: 1687 | K20: 1464 | N20: SEC 10-K
A21: Accounts receivable, net | B21: 3677 | C21: 3498 | D21: 4272 | E21: 2749 | F21: 4463 | G21: 4667 | H21: 4131 | I21: 4427 | J21: 4717 | K21: 5931 | N21: SEC 10-K
A22: Inventories | B22: 5055 | C22: 5261 | D22: 5622 | E22: 7367 | F22: 6854 | G22: 8420 | H22: 8454 | I22: 7519 | J22: 7489 | K22: 7501 | N22: SEC 10-K
A23: Prepaid expenses and other current assets | B23: 1150 | C23: 1130 | D23: 1968 | E23: 1653 | F23: 1498 | G23: 2129 | H23: 1942 | I23: 1854 | J23: 2005 | K23: 2144 | N23: SEC 10-K
A24: Accounts payable | B24: 2048 | C24: 2279 | D24: 2612 | E24: 2248 | F24: 2836 | G24: 3358 | H24: 2862 | I24: 2851 | J24: 3479 | K24: 3600 | N24: SEC 10-K
A25: Accrued liabilities | B25: 3011 | C25: 3269 | D25: 5010 | E25: 5184 | F25: 6063 | G25: 6220 | H25: 5723 | I25: 5725 | J25: 5916 | K25: 6092 | N25: SEC 10-K
A26: Long-term debt, non-current | B26: 3471 | C26: 3468 | D26: 3464 | E26: 9406 | F26: 9413 | G26: 8920 | H26: 8927 | I26: 7903 | J26: 7961 | K26: 5942 | N26: SEC 10-K
A27: Current portion of long-term debt | B27: 6 | C27: 6 | D27: 6 | E27: 3 | F27: 0 | G27: 500 | H27: 0 | I27: 1000 | J27: 0 | K27: 2000 | N27: SEC 10-K
A28: Notes payable / short-term borrowings | B28: 325 | C28: 336 | D28: 9 | E28: 248 | F28: 2 | G28: 10 | H28: 6 | I28: 6 | J28: 5 | K28: 0 | N28: SEC 10-K (FY2026 not tagged; counted as 0)
A29: Shareholders' equity | B29: 12407 | C29: 9812 | D29: 9040 | E29: 8055 | F29: 12767 | G29: 15281 | H29: 14004 | I29: 14430 | J29: 13213 | K29: 14865 | N29: SEC 10-K
A30: Operating working capital | B30: =B21+B22+B23-B24-B25 -> 4823 | C30: =C21+C22+C23-C24-C25 -> 4341 | D30: =D21+D22+D23-D24-D25 -> 4240 | E30: =E21+E22+E23-E24-E25 -> 4337 | F30: =F21+F22+F23-F24-F25 -> 3916 | G30: =G21+G22+G23-G24-G25 -> 5638 | H30: =H21+H22+H23-H24-H25 -> 5942 | I30: =I21+I22+I23-I24-I25 -> 5224 | ... K30: =K21+K22+K23-K24-K25 -> 5884 | N30: Receivables + inventories + prepaid - payables - accrued liabilities
A31: Total debt (excl. leases) | B31: =B26+B27+B28 -> 3802 | C31: =C26+C27+C28 -> 3810 | D31: =D26+D27+D28 -> 3479 | E31: =E26+E27+E28 -> 9657 | F31: =F26+F27+F28 -> 9415 | G31: =G26+G27+G28 -> 9430 | H31: =H26+H27+H28 -> 8933 | I31: =I26+I27+I28 -> 8909 | ... K31: =K26+K27+K28 -> 7942 | N31: Sum of the three debt lines
A32: Ratios (all formulas)
A33: Revenue growth | C33: =C6/B6-1 -> 0.059592431 | D33: =D6/C6-1 -> 0.074731434 | E33: =E6/D6-1 -> -0.043817266 | F33: =F6/E6-1 -> 0.1907601 | G33: =G6/F6-1 -> 0.048767345 | H33: =H6/G6-1 -> 0.096488975 | I33: =I6/H6-1 -> 0.0028310912 | J33: =J6/I6-1 -> -0.098380125 | K33: =K6/J6-1 -> 0.0019218726 | L33: =AVERAGE(C33:K33) -> 0.036988428 | M33: =AVERAGE(G33:K33) -> 0.010325832 | N33: Revenue / last year's revenue - 1
A34: Gross margin | B34: =B7/B6 -> 0.44576419 | C34: =C7/C6 -> 0.43838778 | D34: =D7/D6 -> 0.44671115 | E34: =E7/E6 -> 0.43421651 | F34: =F7/F6 -> 0.44820154 | G34: =G7/G6 -> 0.45983729 | H34: =H7/H6 -> 0.43524611 | I34: =I7/I6 -> 0.44560181 | ... K34: =K7/K6 -> 0.42913488 | L34: =AVERAGE(B34:K34) -> 0.4410448 | M34: =AVERAGE(G34:K34) -> 0.43943336 | N34: Gross profit / revenue
A35: Operating margin | B35: =B9/B6 -> 0.13825328 | C35: =C9/C6 -> 0.12212545 | D35: =D9/D6 -> 0.121993 | E35: =E9/E6 -> 0.08328209 | F35: =F9/F6 -> 0.15575464 | G35: =G9/G6 -> 0.14290302 | H35: =H9/H6 -> 0.115489 | I35: =I9/I6 -> 0.12287294 | ... K35: =K9/K6 -> 0.081835424 | L35: =AVERAGE(B35:K35) -> 0.11644501 | M35: =AVERAGE(G35:K35) -> 0.10860833 | N35: Operating income / revenue
A36: Effective tax rate | B36: =B11/B10 -> 0.13221449 | C36: =C11/C10 -> 0.55306358 | D36: =D11/D10 -> 0.16079983 | E36: =E11/E10 -> 0.12054035 | F36: =F11/F10 -> 0.14021919 | G36: =G11/G10 -> 0.090963765 | H36: =H11/H10 -> 0.18238994 | I36: =I11/I10 -> 0.14925373 | ... K36: =K11/K10 -> 0.20307692 | L36: =AVERAGE(B36:K36) -> 0.19039504 | M36: =AVERAGE(G36:K36) -> 0.15942259 | N36: Income tax / pretax income (FY2018 includes the one-off US tax reform charge)
A37: D&A, % of revenue | B37: =B15/B6 -> 0.02055313 | C37: =C15/C6 -> 0.02052367 | D37: =D15/D6 -> 0.018022855 | E37: =E15/E6 -> 0.019276529 | F37: =F15/F6 -> 0.016704836 | G37: =G15/G6 -> 0.015350032 | H37: =H15/H6 -> 0.013725911 | I37: =I15/I6 -> 0.015497839 | ... K37: =K15/K6 -> 0.016099832 | L37: =AVERAGE(B37:K37) -> 0.017249004 | M37: =AVERAGE(G37:K37) -> 0.015481804 | N37: D&A / revenue
A38: Capex, % of revenue | B38: =B16/B6 -> 0.03216885 | C38: =C16/C6 -> 0.028244086 | D38: =D16/D6 -> 0.028606488 | E38: =E16/E6 -> 0.029035104 | F38: =F16/F6 -> 0.015604652 | G38: =G16/G6 -> 0.016227788 | H38: =H16/H6 -> 0.018919499 | I38: =I16/I6 -> 0.015809353 | ... K38: =K16/K6 -> 0.014742015 | L38: =AVERAGE(B38:K38) -> 0.020864329 | M38: =AVERAGE(G38:K38) -> 0.014996822 | N38: Capex / revenue
A39: Operating working capital, % of revenue | B39: =B30/B6 -> 0.14040757 | C39: =C30/C6 -> 0.11926807 | D39: =D30/D6 -> 0.10839277 | E39: =E30/E6 -> 0.11595327 | F39: =F30/F6 -> 0.087924918 | G39: =G30/G6 -> 0.12070221 | H39: =H30/H6 -> 0.11601617 | I39: =I30/I6 -> 0.10170943 | ... K39: =K30/K6 -> 0.12681581 | L39: =AVERAGE(B39:K39) -> 0.11411873 | M39: =AVERAGE(G39:K39) -> 0.11384814 | N39: Operating working capital / revenue
A40: Free cash flow margin | B40: =B17/B6 -> 0.079796215 | C40: =C17/C6 -> 0.10789351 | D40: =D17/D6 -> 0.12229977 | E40: =E17/E6 -> 0.037403417 | F40: =F17/F6 -> 0.13386322 | G40: =G17/G6 -> 0.094840505 | H40: =H17/H6 -> 0.095124666 | I40: =I17/I6 -> 0.12883065 | ... K40: =K17/K6 -> 0.047070994 | L40: =AVERAGE(B40:K40) -> 0.091769238 | M40: =AVERAGE(G40:K40) -> 0.087287251 | N40: FCF / revenue
A41: Revenue growth per year, compounded FY2017-FY2024 (before the downturn) | B41: =(I6/B6)^(1/7)-1 -> 0.059154491 | N41: (FY2024 revenue / FY2017 revenue) ^ (1/7) - 1

Sheet Sources
A1: Sources: the SEC filing behind every historical number
A2: Rule: for each fiscal year, the value from the most recently filed 10-K (picks up restatements). Look up a filing on EDGAR by its accession number.
A4: Item | B4: Fiscal year | C4: Value (USD m) | D4: XBRL tag | E4: Form | F4: Accession number | G4: Filed | H4: Period end
A5: Revenue | B5: 2017 | C5: 34350 | D5: RevenueFromContractWithCustomerExcludingAssessedTax | E5: 10-K | F5: 0000320187-19-000051 | G5: 2019-07-23 | H5: 2017-05-31
A6: Revenue | B6: 2018 | C6: 36397 | D6: RevenueFromContractWithCustomerExcludingAssessedTax | E6: 10-K | F6: 0000320187-20-000047 | G6: 2020-07-24 | H6: 2018-05-31
A7: Revenue | B7: 2019 | C7: 39117 | D7: RevenueFromContractWithCustomerExcludingAssessedTax | E7: 10-K | F7: 0000320187-21-000028 | G7: 2021-07-20 | H7: 2019-05-31
A8: Revenue | B8: 2020 | C8: 37403 | D8: RevenueFromContractWithCustomerExcludingAssessedTax | E8: 10-K | F8: 0000320187-22-000038 | G8: 2022-07-21 | H8: 2020-05-31
A9: Revenue | B9: 2021 | C9: 44538 | D9: RevenueFromContractWithCustomerExcludingAssessedTax | E9: 10-K | F9: 0000320187-23-000039 | G9: 2023-07-20 | H9: 2021-05-31
A10: Revenue | B10: 2022 | C10: 46710 | D10: RevenueFromContractWithCustomerExcludingAssessedTax | E10: 10-K | F10: 0000320187-24-000044 | G10: 2024-07-25 | H10: 2022-05-31
A11: Revenue | B11: 2023 | C11: 51217 | D11: RevenueFromContractWithCustomerExcludingAssessedTax | E11: 10-K | F11: 0000320187-25-000047 | G11: 2025-07-17 | H11: 2023-05-31
A12: Revenue | B12: 2024 | C12: 51362 | D12: RevenueFromContractWithCustomerExcludingAssessedTax | E12: 10-K | F12: 0000320187-26-000088 | G12: 2026-07-15 | H12: 2024-05-31
A13: Revenue | B13: 2025 | C13: 46309 | D13: RevenueFromContractWithCustomerExcludingAssessedTax | E13: 10-K | F13: 0000320187-26-000088 | G13: 2026-07-15 | H13: 2025-05-31
A14: Revenue | B14: 2026 | C14: 46398 | D14: RevenueFromContractWithCustomerExcludingAssessedTax | E14: 10-K | F14: 0000320187-26-000088 | G14: 2026-07-15 | H14: 2026-05-31
A15: Gross profit | B15: 2017 | C15: 15312 | D15: GrossProfit | E15: 10-K | F15: 0000320187-19-000051 | G15: 2019-07-23 | H15: 2017-05-31
A16: Gross profit | B16: 2018 | C16: 15956 | D16: GrossProfit | E16: 10-K | F16: 0000320187-20-000047 | G16: 2020-07-24 | H16: 2018-05-31
... A253: Accrued liabilities | B253: 2026 | C253: 6092 | D253: AccruedLiabilitiesCurrent | E253: 10-K | F253: 0000320187-26-000088 | G253: 2026-07-15 | H253: 2026-05-31

Sheet WACC
A1: WACC: the yearly return Nike's investors require (the discount rate)
A2: Green = pulled from the Assumptions tab. Black = calculated here.
A4: Step | B4: Value | C4: Formula in words
A5: Cost of equity (what shareholders expect)
A6: Risk-free rate | B6: =Risk_Free -> 0.05277 | C6: From Assumptions
A7: Beta | B7: =Nike_Beta -> 1.092 | C7: From Assumptions
A8: Equity risk premium | B8: =ERP -> 0.0409 | C8: From Assumptions
A9: Cost of equity | B9: =Risk_Free+Nike_Beta*ERP -> 0.0974328 | C9: Risk-free rate + beta x equity risk premium (CAPM)
A11: Cost of debt (what lenders charge, after the tax saving)
A12: Pre-tax cost of debt | B12: =Risk_Free+Debt_Spread -> 0.06077 | C12: Risk-free rate + Nike's borrowing spread
A13: After-tax cost of debt | B13: =Pretax_Cost_Of_Debt*(1-Tax_On_Interest) -> 0.0480083 | C13: Interest is tax-deductible, so the real cost is lower: pre-tax cost x (1 - tax rate)
A15: Weights (market values today)
A16: Market value of equity (USD m) | B16: =Share_Price*Shares -> 50269.854 | C16: Share price x diluted shares
A17: Debt, excl. leases (USD m) | B17: =Debt_LT_Noncurrent+Debt_LT_Current+Debt_Short_Term -> 7893 | C17: Book value of debt from the 10-Q (used as a stand-in for its market value)
A18: Weight of equity | B18: =Market_Cap/(Market_Cap+Total_Debt) -> 0.86429483 | C18: Equity / (equity + debt)
A19: Weight of debt | B19: =Total_Debt/(Market_Cap+Total_Debt) -> 0.13570517 | C19: Debt / (equity + debt)
A21: WACC | B21: =Weight_Equity*Cost_Of_Equity+Weight_Debt*After_Tax_Cost_Of_Debt -> 0.09072564 | C21: Weight of equity x cost of equity + weight of debt x after-tax cost of debt

Sheet Forecast
A1: Forecast: FY2027-FY2031 (USD millions), from revenue down to free cash flow
A2: Column B is FY2026 actual (green, from Historicals) run through the same formulas. Columns C-G are the forecast, driven only by the Assumptions tab.
A4: Line | B4: FY2026 actual | C4: FY2027 forecast | D4: FY2028 forecast | E4: FY2029 forecast | F4: FY2030 forecast | G4: FY2031 forecast | H4: How it is calculated
A5: Year number (t) | B5: =0 -> 0 | C5: =1 -> 1 | D5: =2 -> 2 | E5: =3 -> 3 | F5: =4 -> 4 | G5: =5 -> 5 | H5: 0 = FY2026, the last actual year
A6: Revenue growth | B6: =Historicals!K33 -> 0.0019218726 | C6: =Growth_FY2027+IF(1=1,0,Growth_Adjustment) -> -0.08 | D6: =Growth_FY2028+IF(2=1,0,Growth_Adjustment) -> 0.03 | E6: =Growth_FY2029+IF(3=1,0,Growth_Adjustment) -> 0.04 | F6: =Growth_FY2030+IF(4=1,0,Growth_Adjustment) -> 0.04 | G6: =Growth_FY2031+IF(5=1,0,Growth_Adjustment) -> 0.04 | H6: Growth input for that year + the scenario adjustment (Assumptions); FY2027 is Nike's guidance, no adjustment
A7: Revenue | B7: =Historicals!K6 -> 46398 | C7: =B7*(1+C6) -> 42686.16 | D7: =C7*(1+D6) -> 43966.745 | E7: =D7*(1+E6) -> 45725.415 | F7: =E7*(1+F6) -> 47554.431 | G7: =F7*(1+G6) -> 49456.608 | H7: Last year's revenue x (1 + growth)
A8: Operating margin | B8: =Historicals!K35 -> 0.081835424 | C8: =IF(C5=1,FY2027_Margin,FY2027_Margin+(Target_Margin-FY2027_Margin)*MIN(C5-1,Years_To_Target-1)/(Years_To_Target-1)) -> 0.0555 | D8: =IF(D5=1,FY2027_Margin,FY2027_Margin+(Target_Margin-FY2027_Margin)*MIN(D5-1,Years_To_Target-1)/(Years_To_Target-1)) -> 0.072875 | E8: =IF(E5=1,FY2027_Margin,FY2027_Margin+(Target_Margin-FY2027_Margin)*MIN(E5-1,Years_To_Target-1)/(Years_To_Target-1)) -> 0.09025 | F8: =IF(F5=1,FY2027_Margin,FY2027_Margin+(Target_Margin-FY2027_Margin)*MIN(F5-1,Years_To_Target-1)/(Years_To_Target-1)) -> 0.107625 | G8: =IF(G5=1,FY2027_Margin,FY2027_Margin+(Target_Margin-FY2027_Margin)*MIN(G5-1,Years_To_Target-1)/(Years_To_Target-1)) -> 0.125 | H8: FY2027 = guidance margin; then a straight line to the target, reached in FY2031, then stays at the target
A9: Operating income | B9: =B7*B8 -> 3797 | C9: =C7*C8 -> 2369.0819 | D9: =D7*D8 -> 3204.0765 | E9: =E7*E8 -> 4126.7187 | F9: =F7*F8 -> 5118.0457 | G9: =G7*G8 -> 6182.0761 | H9: Revenue x operating margin
A10: Taxes on operating income | B10: =B9*Tax_Rate -> 683.46 | C10: =C9*Tax_Rate -> 426.43474 | D10: =D9*Tax_Rate -> 576.73377 | E10: =E9*Tax_Rate -> 742.80936 | F10: =F9*Tax_Rate -> 921.24822 | G10: =G9*Tax_Rate -> 1112.7737 | H10: Operating income x tax rate (taxes as if Nike had no debt)
A11: NOPAT (after-tax operating income) | B11: =B9-B10 -> 3113.54 | C11: =C9-C10 -> 1942.6471 | D11: =D9-D10 -> 2627.3428 | E11: =E9-E10 -> 3383.9093 | F11: =F9-F10 -> 4196.7974 | G11: =G9-G10 -> 5069.3024 | H11: Operating income - taxes
A12: Plus: depreciation & amortization | B12: =Historicals!K15 -> 747 | C12: =C7*DA_Pct -> 725.66472 | D12: =D7*DA_Pct -> 747.43466 | E12: =E7*DA_Pct -> 777.33205 | F12: =F7*DA_Pct -> 808.42533 | G12: =G7*DA_Pct -> 840.76234 | H12: Revenue x D&A % (added back: it is an expense but not a cash payment)
A13: Less: capital expenditures | B13: =Historicals!K16 -> 684 | C13: =C7*Capex_Pct -> 853.7232 | D13: =D7*Capex_Pct -> 879.3349 | E13: =E7*Capex_Pct -> 914.50829 | F13: =F7*Capex_Pct -> 951.08862 | G13: =G7*Capex_Pct -> 989.13217 | H13: Revenue x capex % (cash spent on stores, offices, equipment, software)
A14: Operating working capital (balance at year end) | B14: =Historicals!K30 -> 5884 | C14: =C7*NWC_Pct -> 4908.9084 | D14: =D7*NWC_Pct -> 5056.1757 | E14: =E7*NWC_Pct -> 5258.4227 | F14: =F7*NWC_Pct -> 5468.7596 | G14: =G7*NWC_Pct -> 5687.51 | H14: Revenue x working capital % (inventory + receivables etc. - payables)
A15: Less: increase in working capital | B15: =B14-Historicals!J30 -> 1068 | C15: =C14-B14 -> -975.0916 | D15: =D14-C14 -> 147.26725 | E15: =E14-D14 -> 202.24703 | F15: =F14-E14 -> 210.33691 | G15: =G14-F14 -> 218.75038 | H15: This year's working capital - last year's (a decrease frees up cash)
A16: Free cash flow to the firm (FCFF) | B16: =B11+B12-B13-B15 -> 2108.54 | C16: =C11+C12-C13-C15 -> 2789.6803 | D16: =D11+D12-D13-D15 -> 2348.1753 | E16: =E11+E12-E13-E15 -> 3044.486 | F16: =F11+F12-F13-F15 -> 3843.7972 | G16: =G11+G12-G13-G15 -> 4702.1822 | H16: NOPAT + D&A - capex - increase in working capital: cash available to all investors
A18: Checks and comparisons
A19: FCFF margin | B19: =B16/B7 -> 0.045444631 | C19: =C16/C7 -> 0.065353273 | D19: =D16/D7 -> 0.053407985 | E19: =E16/E7 -> 0.066581923 | F19: =F16/F7 -> 0.080829423 | G19: =G16/G7 -> 0.095076923 | H19: FCFF / revenue
A20: Net reinvestment | B20: =B13-B12+B15 -> 1005 | C20: =C13-C12+C15 -> -847.03312 | D20: =D13-D12+D15 -> 279.16749 | E20: =E13-E12+E15 -> 339.42327 | F20: =F13-F12+F15 -> 353.0002 | G20: =G13-G12+G15 -> 367.12021 | H20: Capex - D&A + increase in working capital (the reverse DCF used change in revenue / 3.2 instead)
A21: Simple FCF reported in FY2026 (operating cash flow - capex) | B21: =Historicals!K17 -> 2184 | H21: For comparison with column B's FCFF. They differ because FCFF uses a normalized 18% tax on operating income and excludes interest and other income.

Sheet Valuation
A1: Valuation: from forecast cash flows to value per share
A2: Each year's cash flow is worth less the further away it is: divide it by (1 + WACC) once per year between the valuation date and the end of that fiscal year.
A4: Part 1: present value of FY2027-FY2031 cash flows | B4: FY2027 | C4: FY2028 | D4: FY2029 | E4: FY2030 | F4: FY2031 | G4: How it is calculated
A5: Fiscal year end | B5: =DATE(2027,5,31) -> 46538 | C5: =DATE(2028,5,31) -> 46904 | D5: =DATE(2029,5,31) -> 47269 | E5: =DATE(2030,5,31) -> 47634 | F5: =DATE(2031,5,31) -> 47999 | G5: Nike's fiscal year ends May 31
A6: Years from valuation date | B6: =(B5-Valuation_Date)/365.25 -> 0.65982204 | C6: =(C5-Valuation_Date)/365.25 -> 1.6618754 | D6: =(D5-Valuation_Date)/365.25 -> 2.661191 | E6: =(E5-Valuation_Date)/365.25 -> 3.6605065 | F6: =(F5-Valuation_Date)/365.25 -> 4.659822 | G6: (Year-end date - valuation date) / 365.25 days
A7: Share of the year's cash flow counted | B7: =Share_Of_FY2027_Remaining -> 0.75 | C7: 1 | D7: 1 | E7: 1 | F7: 1 | G7: FY2027: only Sep-May are still to come (Jun-Aug cash is already in the 10-Q balance sheet)
A8: FCFF (from Forecast) | B8: =Forecast!C16 -> 2789.6803 | C8: =Forecast!D16 -> 2348.1753 | D8: =Forecast!E16 -> 3044.486 | E8: =Forecast!F16 -> 3843.7972 | F8: =Forecast!G16 -> 4702.1822 | G8: Forecast tab, FCFF row
A9: FCFF counted | B9: =B8*B7 -> 2092.2602 | C9: =C8*C7 -> 2348.1753 | D9: =D8*D7 -> 3044.486 | E9: =E8*E7 -> 3843.7972 | F9: =F8*F7 -> 4702.1822 | G9: FCFF x share counted
A10: Discount factor | B10: =1/(1+WACC)^B6 -> 0.94430974 | C10: =1/(1+WACC)^C6 -> 0.86560848 | D10: =1/(1+WACC)^D6 -> 0.79365507 | E10: =1/(1+WACC)^E6 -> 0.72768276 | F10: =1/(1+WACC)^F6 -> 0.66719438 | G10: 1 / (1 + WACC) ^ years
A11: Present value of FCFF | B11: =B9*B10 -> 1975.7417 | C11: =C9*C10 -> 2032.6004 | D11: =D9*D10 -> 2416.2718 | E11: =E9*E10 -> 2797.065 | F11: =F9*F10 -> 3137.2695 | G11: FCFF counted x discount factor
A13: Part 2: from enterprise value to value per share | B13: Value | C13: How it is calculated
A14: Sum of present values, FY2027-FY2031 (USD m) | B14: =SUM(B11:F11) -> 12358.948 | C14: Add up Part 1's last row
A15: WACC | B15: =WACC -> 0.09072564 | C15: From the WACC tab
A16: Terminal growth | B16: =Terminal_Growth -> 0.025 | C16: From Assumptions
A17: FY2032 revenue (USD m) | B17: =Forecast!G7*(1+Terminal_Growth) -> 50693.024 | C17: FY2031 revenue x (1 + terminal growth)
A18: FY2032 FCFF (first year after the forecast) (USD m) | B18: =Revenue_FY2032*(Forecast!G8*(1-Tax_Rate)+DA_Pct-Capex_Pct)-NWC_Pct*(Revenue_FY2032-Forecast!G7) -> 4901.7681 | C18: FY2032 revenue x (FY2031 margin x (1 - tax) + D&A % - capex %) - working capital % x revenue increase: a steady year growing at the terminal rate
A19: Terminal value at end of FY2031 (USD m) | B19: =FCFF_FY2032/(WACC-Terminal_Growth) -> 74579.238 | C19: FY2032 FCFF / (WACC - terminal growth): value of all cash flows after FY2031 (growing-perpetuity formula)
A20: Present value of terminal value (USD m) | B20: =Terminal_Value*F10 -> 49758.848 | C20: Terminal value x FY2031 discount factor
A21: Enterprise value (USD m) | B21: =Sum_PV_FCFF+PV_Terminal_Value -> 62117.796 | C21: Value of the business to all investors (debt + equity)
A22: Plus: cash and short-term investments (USD m) | B22: =Cash+ST_Investments -> 8368 | C22: From Assumptions (10-Q, 2026-08-31)
A23: Less: debt, excl. leases (USD m) | B23: =Total_Debt -> 7893 | C23: From the WACC tab
A24: Equity value (USD m) | B24: =Enterprise_Value+B22-B23 -> 62592.796 | C24: Enterprise value + cash - debt: what belongs to shareholders
A25: Diluted shares (millions) | B25: =Shares -> 1484.2 | C25: From Assumptions
A26: Value per share (USD) | B26: =Equity_Value/Shares -> 42.172751 | C26: Equity value / shares
A27: Share price on valuation date (USD) | B27: =Share_Price -> 33.87 | C27: From Assumptions
A28: Value vs price | B28: =Value_Per_Share/Share_Price-1 -> 0.24513583 | C28: Positive = the model says the shares are worth more than the price
A29: Terminal value as % of enterprise value | B29: =PV_Terminal_Value/Enterprise_Value -> 0.80104014 | C29: How much of the value comes from after FY2031 (high = more depends on the long run)
A30: Implied EV / FY2026 operating income | B30: =Enterprise_Value/Forecast!B9 -> 16.359704 | C30: A sanity check multiple
A32: Part 3: value per share (USD) for other discount rates and terminal growth rates
A33: Terminal growth (down) / WACC (across) | B33: =WACC+(-2)*Sens_WACC_Step -> 0.08072564 | C33: =WACC+(-1)*Sens_WACC_Step -> 0.08572564 | D33: =WACC+(0)*Sens_WACC_Step -> 0.09072564 | E33: =WACC+(1)*Sens_WACC_Step -> 0.09572564 | F33: =WACC+(2)*Sens_WACC_Step -> 0.10072564
A34: =Terminal_Growth+(-2)*Sens_Growth_Step -> 0.015 | B34: =(SUMPRODUCT($B$9:$F$9,1/(1+B$33)^$B$6:$F$6)+(Forecast!$G$7*(1+$A34)*(Forecast!$G$8*(1-Tax_Rate)+DA_Pct-Capex_Pct)-NWC_Pct*Forecast!$G$7*$A34)/(B$33-$A34)/(1+B$33)^$F$6+Cash+ST_Investments-Total_Debt)/Shares -> 43.924656 | C34: =(SUMPRODUCT($B$9:$F$9,1/(1+C$33)^$B$6:$F$6)+(Forecast!$G$7*(1+$A34)*(Forecast!$G$8*(1-Tax_Rate)+DA_Pct-Capex_Pct)-NWC_Pct*Forecast!$G$7*$A34)/(C$33-$A34)/(1+C$33)^$F$6+Cash+ST_Investments-Total_Debt)/Shares -> 40.63892 | D34: =(SUMPRODUCT($B$9:$F$9,1/(1+D$33)^$B$6:$F$6)+(Forecast!$G$7*(1+$A34)*(Forecast!$G$8*(1-Tax_Rate)+DA_Pct-Capex_Pct)-NWC_Pct*Forecast!$G$7*$A34)/(D$33-$A34)/(1+D$33)^$F$6+Cash+ST_Investments-Total_Debt)/Shares -> 37.790998 | E34: =(SUMPRODUCT($B$9:$F$9,1/(1+E$33)^$B$6:$F$6)+(Forecast!$G$7*(1+$A34)*(Forecast!$G$8*(1-Tax_Rate)+DA_Pct-Capex_Pct)-NWC_Pct*Forecast!$G$7*$A34)/(E$33-$A34)/(1+E$33)^$F$6+Cash+ST_Investments-Total_Debt)/Shares -> 35.299449 | F34: =(SUMPRODUCT($B$9:$F$9,1/(1+F$33)^$B$6:$F$6)+(Forecast!$G$7*(1+$A34)*(Forecast!$G$8*(1-Tax_Rate)+DA_Pct-Capex_Pct)-NWC_Pct*Forecast!$G$7*$A34)/(F$33-$A34)/(1+F$33)^$F$6+Cash+ST_Investments-Total_Debt)/Shares -> 33.101836
A35: =Terminal_Growth+(-1)*Sens_Growth_Step -> 0.02 | B35: =(SUMPRODUCT($B$9:$F$9,1/(1+B$33)^$B$6:$F$6)+(Forecast!$G$7*(1+$A35)*(Forecast!$G$8*(1-Tax_Rate)+DA_Pct-Capex_Pct)-NWC_Pct*Forecast!$G$7*$A35)/(B$33-$A35)/(1+B$33)^$F$6+Cash+ST_Investments-Total_Debt)/Shares -> 46.781023 | C35: =(SUMPRODUCT($B$9:$F$9,1/(1+C$33)^$B$6:$F$6)+(Forecast!$G$7*(1+$A35)*(Forecast!$G$8*(1-Tax_Rate)+DA_Pct-Capex_Pct)-NWC_Pct*Forecast!$G$7*$A35)/(C$33-$A35)/(1+C$33)^$F$6+Cash+ST_Investments-Total_Debt)/Shares -> 43.03734 | D35: =(SUMPRODUCT($B$9:$F$9,1/(1+D$33)^$B$6:$F$6)+(Forecast!$G$7*(1+$A35)*(Forecast!$G$8*(1-Tax_Rate)+DA_Pct-Capex_Pct)-NWC_Pct*Forecast!$G$7*$A35)/(D$33-$A35)/(1+D$33)^$F$6+Cash+ST_Investments-Total_Debt)/Shares -> 39.826989 | E35: =(SUMPRODUCT($B$9:$F$9,1/(1+E$33)^$B$6:$F$6)+(Forecast!$G$7*(1+$A35)*(Forecast!$G$8*(1-Tax_Rate)+DA_Pct-Capex_Pct)-NWC_Pct*Forecast!$G$7*$A35)/(E$33-$A35)/(1+E$33)^$F$6+Cash+ST_Investments-Total_Debt)/Shares -> 37.044235 | F35: =(SUMPRODUCT($B$9:$F$9,1/(1+F$33)^$B$6:$F$6)+(Forecast!$G$7*(1+$A35)*(Forecast!$G$8*(1-Tax_Rate)+DA_Pct-Capex_Pct)-NWC_Pct*Forecast!$G$7*$A35)/(F$33-$A35)/(1+F$33)^$F$6+Cash+ST_Investments-Total_Debt)/Shares -> 34.609544
A36: =Terminal_Growth+(0)*Sens_Growth_Step -> 0.025 | B36: =(SUMPRODUCT($B$9:$F$9,1/(1+B$33)^$B$6:$F$6)+(Forecast!$G$7*(1+$A36)*(Forecast!$G$8*(1-Tax_Rate)+DA_Pct-Capex_Pct)-NWC_Pct*Forecast!$G$7*$A36)/(B$33-$A36)/(1+B$33)^$F$6+Cash+ST_Investments-Total_Debt)/Shares -> 50.149967 | C36: =(SUMPRODUCT($B$9:$F$9,1/(1+C$33)^$B$6:$F$6)+(Forecast!$G$7*(1+$A36)*(Forecast!$G$8*(1-Tax_Rate)+DA_Pct-Capex_Pct)-NWC_Pct*Forecast!$G$7*$A36)/(C$33-$A36)/(1+C$33)^$F$6+Cash+ST_Investments-Total_Debt)/Shares -> 45.83072 | D36: =(SUMPRODUCT($B$9:$F$9,1/(1+D$33)^$B$6:$F$6)+(Forecast!$G$7*(1+$A36)*(Forecast!$G$8*(1-Tax_Rate)+DA_Pct-Capex_Pct)-NWC_Pct*Forecast!$G$7*$A36)/(D$33-$A36)/(1+D$33)^$F$6+Cash+ST_Investments-Total_Debt)/Shares -> 42.172751 | E36: =(SUMPRODUCT($B$9:$F$9,1/(1+E$33)^$B$6:$F$6)+(Forecast!$G$7*(1+$A36)*(Forecast!$G$8*(1-Tax_Rate)+DA_Pct-Capex_Pct)-NWC_Pct*Forecast!$G$7*$A36)/(E$33-$A36)/(1+E$33)^$F$6+Cash+ST_Investments-Total_Debt)/Shares -> 39.035719 | F36: =(SUMPRODUCT($B$9:$F$9,1/(1+F$33)^$B$6:$F$6)+(Forecast!$G$7*(1+$A36)*(Forecast!$G$8*(1-Tax_Rate)+DA_Pct-Capex_Pct)-NWC_Pct*Forecast!$G$7*$A36)/(F$33-$A36)/(1+F$33)^$F$6+Cash+ST_Investments-Total_Debt)/Shares -> 36.316353
A37: =Terminal_Growth+(1)*Sens_Growth_Step -> 0.03 | B37: =(SUMPRODUCT($B$9:$F$9,1/(1+B$33)^$B$6:$F$6)+(Forecast!$G$7*(1+$A37)*(Forecast!$G$8*(1-Tax_Rate)+DA_Pct-Capex_Pct)-NWC_Pct*Forecast!$G$7*$A37)/(B$33-$A37)/(1+B$33)^$F$6+Cash+ST_Investments-Total_Debt)/Shares -> 54.183061 | C37: =(SUMPRODUCT($B$9:$F$9,1/(1+C$33)^$B$6:$F$6)+(Forecast!$G$7*(1+$A37)*(Forecast!$G$8*(1-Tax_Rate)+DA_Pct-Capex_Pct)-NWC_Pct*Forecast!$G$7*$A37)/(C$33-$A37)/(1+C$33)^$F$6+Cash+ST_Investments-Total_Debt)/Shares -> 49.125374 | D37: =(SUMPRODUCT($B$9:$F$9,1/(1+D$33)^$B$6:$F$6)+(Forecast!$G$7*(1+$A37)*(Forecast!$G$8*(1-Tax_Rate)+DA_Pct-Capex_Pct)-NWC_Pct*Forecast!$G$7*$A37)/(D$33-$A37)/(1+D$33)^$F$6+Cash+ST_Investments-Total_Debt)/Shares -> 44.904801 | E37: =(SUMPRODUCT($B$9:$F$9,1/(1+E$33)^$B$6:$F$6)+(Forecast!$G$7*(1+$A37)*(Forecast!$G$8*(1-Tax_Rate)+DA_Pct-Capex_Pct)-NWC_Pct*Forecast!$G$7*$A37)/(E$33-$A37)/(1+E$33)^$F$6+Cash+ST_Investments-Total_Debt)/Shares -> 41.330202 | F37: =(SUMPRODUCT($B$9:$F$9,1/(1+F$33)^$B$6:$F$6)+(Forecast!$G$7*(1+$A37)*(Forecast!$G$8*(1-Tax_Rate)+DA_Pct-Capex_Pct)-NWC_Pct*Forecast!$G$7*$A37)/(F$33-$A37)/(1+F$33)^$F$6+Cash+ST_Investments-Total_Debt)/Shares -> 38.26449
A38: =Terminal_Growth+(2)*Sens_Growth_Step -> 0.035 | B38: =(SUMPRODUCT($B$9:$F$9,1/(1+B$33)^$B$6:$F$6)+(Forecast!$G$7*(1+$A38)*(Forecast!$G$8*(1-Tax_Rate)+DA_Pct-Capex_Pct)-NWC_Pct*Forecast!$G$7*$A38)/(B$33-$A38)/(1+B$33)^$F$6+Cash+ST_Investments-Total_Debt)/Shares -> 59.098175 | C38: =(SUMPRODUCT($B$9:$F$9,1/(1+C$33)^$B$6:$F$6)+(Forecast!$G$7*(1+$A38)*(Forecast!$G$8*(1-Tax_Rate)+DA_Pct-Capex_Pct)-NWC_Pct*Forecast!$G$7*$A38)/(C$33-$A38)/(1+C$33)^$F$6+Cash+ST_Investments-Total_Debt)/Shares -> 53.069533 | D38: =(SUMPRODUCT($B$9:$F$9,1/(1+D$33)^$B$6:$F$6)+(Forecast!$G$7*(1+$A38)*(Forecast!$G$8*(1-Tax_Rate)+DA_Pct-Capex_Pct)-NWC_Pct*Forecast!$G$7*$A38)/(D$33-$A38)/(1+D$33)^$F$6+Cash+ST_Investments-Total_Debt)/Shares -> 48.127119 | E38: =(SUMPRODUCT($B$9:$F$9,1/(1+E$33)^$B$6:$F$6)+(Forecast!$G$7*(1+$A38)*(Forecast!$G$8*(1-Tax_Rate)+DA_Pct-Capex_Pct)-NWC_Pct*Forecast!$G$7*$A38)/(E$33-$A38)/(1+E$33)^$F$6+Cash+ST_Investments-Total_Debt)/Shares -> 44.002529 | F38: =(SUMPRODUCT($B$9:$F$9,1/(1+F$33)^$B$6:$F$6)+(Forecast!$G$7*(1+$A38)*(Forecast!$G$8*(1-Tax_Rate)+DA_Pct-Capex_Pct)-NWC_Pct*Forecast!$G$7*$A38)/(F$33-$A38)/(1+F$33)^$F$6+Cash+ST_Investments-Total_Debt)/Shares -> 40.509032
A39: The centre cell equals the value per share above. Each cell repeats Part 1 and Part 2 with that row's growth and that column's WACC.
A41: Part 4: comparison with the reverse DCF (output/04_reverse_dcf_results.md)
A42: The reverse DCFs (scripts 04 and 06) run this same model backwards: they fix the value at the share price and solve for the growth and margin it implies (output/06_implied_growth_and_margin_results.md).
A43: To do the same here, use Excel's Goal Seek: Data > What-If Analysis > Goal Seek, set cell 'Value_Per_Share' to the share price by changing 'Growth_Adjustment' on Assumptions.
A44: Python copy of this model: scripts/dcf_model.py. Script 06 checks the two give the same value to the cent.
